<!-- Hexrobotics.ai MJCF model for the hextech mechahand v13. -->

<mujoco model="hexrobotics_mechahand_right">
  <compiler angle="radian" meshdir="assets" autolimits="true" eulerseq="xyz"/>
  
  <!-- Simulation options.

  Use the default timestep to have the simulation run at 500Hz.
    
  Recommended to increase impratio in order to grab objects better:
    > Settings larger than 1 cause friction forces to be “harder” than normal forces, having 
    > the general effect of preventing slip, without increasing the actual friction coefficient. 
  
  -->
  <option timestep="0.002" impratio="2"/>

  <default>
    <!-- The mesh files are saved in millimiteres. -->
    <default class="millimeter_units">
      <mesh scale="0.001 0.001 0.001"/>
    </default>

    <!-- Settings for range limited hinge joints with constraints tuned for 0.5Nm torque levels and about half a circle of range.
      Use a large damping coefficient to prevent oscillations.
      Use a large solimp to prevent the joint from overshooting the target position.
        Expecting format `dmin, dmax, width, midpoint, power`.
        Need large dmin and dmax to counter the actuator torque, use values up to 5Nm.
        Let the width be 0.05 radians (3degrees), the default is a bit too sharp causes a lot of bouncing.
        Set the midpoint to 0.2 of width, fairly sharp constraint.
        Set the power to 4 to have the impedance increase quickly after the midpoint.
      Use the default solref, but set it explicitly to be aware of solver config.
        Expecting format `timeconst, dampratio`.
        Keep damping ratio at 0.8 for under damping.
        Keep timeconst at 0.01s which is 5 times higher than the default timestep; timeconst deterimines the acceleration imposed by the constraint.
    -->
    <default class="limited_joint">
      <joint damping="0.05" solreflimit="0.01 0.8" solimplimit="0.8 4 0.05 0.2 4" limited="true"/>
    </default>

    <default class="tip_spring_rod_constraint">
      <equality solimp="0 1 0.001 0.5 2" solref="0.005 0.2"/>
    </default>
  </default>

  <!-- Link the 3D model files. -->
  <asset>
    <material name="white" specular="0.5" shininess="0.4" rgba="0.8500 0.8500 0.8500 1.0"/>
    <material name="black_transparent" specular="0.1" shininess="0.1" rgba="0.0000 0.0000 0.0000 0.1"/>

    <mesh class="millimeter_units" file="gimbal_structure.stl"/>
    <mesh class="millimeter_units" file="knuckle_gimbal.stl"/>
    <mesh class="millimeter_units" file="middle_segment.stl"/>
    <mesh class="millimeter_units" file="motor_box.stl"/>
    <mesh class="millimeter_units" file="mount_peg.stl"/>
    <mesh class="millimeter_units" file="palm.stl"/>
    <mesh class="millimeter_units" file="pinkie_pivot.stl"/>
    <mesh class="millimeter_units" file="proximal.stl"/>
    <mesh class="millimeter_units" file="squash_proximal.stl"/>
    <mesh class="millimeter_units" file="thumb_pivot.stl"/>
    <mesh class="millimeter_units" file="tip_spring_rod.stl"/>
    <mesh class="millimeter_units" file="tip.stl"/>
  </asset>

  <!-- Start of model spec. -->
  <worldbody>
    <!-- The mounting peg next to the elbow joint is the ground reference for the hand. -->
    <body name="mount_peg" pos="0 0 0">
      <geom type="mesh" mesh="mount_peg" material="white"/>

      <!-- The wrist is a ball joint made of 3 hinge joints. -->

      <!-- The box of tendon actuators rotates with the palm to avoid twisting the tendons. -->
      <body name="motor_box" pos="0 0 0">
        <inertial mass="0.9" pos="0 0.120 0.010" euler="0 0 1.5708" diaginertia="0.00075 0.00219 0.0024"/>
        <geom type="mesh" mesh="motor_box" material="white"/>
        <joint name="wrist_roll" class="limited_joint" axis="0 1 0" range="-1.0472 1.0472"/><!-- -60degrees 60degrees -->
        <site name="motor_box_IMU" pos="0 0.055 0.030"/>

        <!-- The second hinge joint drives the pitch of the palm. -->
        <body name="gimbal_structure" pos="0 0 0">
          <geom type="mesh" mesh="gimbal_structure" material="white" mass="0.020"/>
          <joint name="wrist_pitch" class="limited_joint" axis="1 0 0" range="-0.436332 0.959931"/><!-- -25degrees 55degrees -->

          <!-- The third hinge joint drives the yaw of the palm. -->  
          <body name="palm" pos="0 -0.005 0">
            <geom type="mesh" mesh="palm" material="white" mass="0.060"/>
            <joint name="wrist_yaw" class="limited_joint" axis="0 0 1" pos="0 0.005 0" range="-0.349066 0.349066"/><!-- -20degrees 20degrees -->

            <site name="palm_inside_left_pressure_sensor" pos="0.014 -0.075 -0.011" type="cylinder" size="0.008 0.001" material="black_transparent"/>
            <site name="palm_inside_right_pressure_sensor" pos="-0.014 -0.075 -0.011" type="cylinder" size="0.008 0.001" material="black_transparent"/>
            <site name="palm_outside_left_pressure_sensor" pos="0.018 -0.065 0.023" euler="0.0872665 0 0" type="cylinder" size="0.016 0.001" material="black_transparent"/>
            <site name="palm_outside_right_pressure_sensor" pos="-0.018 -0.065 0.023" euler="0.0872665 0 0" type="cylinder" size="0.016 0.001" material="black_transparent"/>

            <!-- The thumb pivot is an extra joint to allow the thumb to be opposable. The joint is on axis at 15 degree angle to the center line (the middle finger line). -->
            <body name="thumb_pivot" pos="0 0 0">
              <geom type="mesh" mesh="thumb_pivot" material="white" mass="0.010"/>
              <joint name="thumb_abduct" class="limited_joint" axis="-0.25882 0.96593 0" range="0 1.5708"/><!-- 0degrees 90degrees -->
            
              <!-- The thumb starts at 55mm from the palm origin and an angle of 45 degrees to the center line, followed by twisting 30 degrees around the finger axis. -->
              <body name="thumb_knuckle" pos="0.03889 -0.03889 0" euler="-0.3875967 0.3613671 0.857072 "> 
                <!-- The euler params are the result of applying 2 rotations, also specified by XYZ euler: 0 0 45degeers; 0 30degrees 0. -->
                <geom type="mesh" mesh="knuckle_gimbal" material="white" mass="0.005"/>
                <joint name="thumb_yaw" class="limited_joint" axis="0 0 1" range="-0.523599 0.523599"/><!-- 30degrees 30degrees -->

                <!-- The thumb uses the shorter proximal segment. The axis of the pitch joint is 15mm offset from the yaw axis, due to sensor space constraints. --> 
                <body name="thumb_proximal" pos="0 0 0">
                  <geom type="mesh" mesh="squash_proximal" material="white" mass="0.025"/>
                  <joint name="thumb_pitch" class="limited_joint" axis="1 0 0" pos="0 -0.015 0" range="0 1.5708"/><!-- 0degrees 90degrees -->

                  <!-- The shorter middle segment means the middle segment needs to be offset by 5mm. The joint is at 45mm from the finger yaw axis. -->
                  <body name="thumb_middle" pos="0 0.005 0">
                    <geom type="mesh" mesh="middle_segment" material="white" mass="0.013"/>
                    <joint name="thumb_curl" class="limited_joint" axis="1 0 0" pos="0 -0.045 0" range="0 1.5708"/><!-- 0degrees 90degrees -->

                    <!-- The tip axis joint is 75mm from the yaw axis for the stubbier finger. -->
                    <body name="thumb_tip" pos="0 0 0">
                      <geom type="mesh" mesh="tip" material="white" mass="0.015"/>
                      <joint name="thumb_tip" class="limited_joint" axis="1 0 0" pos="0 -0.075 0" range="0 1.8326" damping="0.01"/><!-- 0degrees 105degrees -->
                      <site name="thumb_tip_joint" pos="0 -0.075 0"/>
                      <site name="thumb_nail_pressure_sensor" pos="0 -0.085 0.0095" type="cylinder" size="0.006 0.001" material="black_transparent"/>
                      <site name="thumb_tip_pressure_sensor" pos="0 -0.090 -0.0055" euler="-0.523599 0 0" type="cylinder" size="0.006 0.001" material="black_transparent"/>
                      <site name="thumb_left_pressure_sensor" pos="0.007 -0.085 0.002" euler="0 1.5708 0" type="cylinder" size="0.006 0.001" material="black_transparent"/>
                      <site name="thumb_right_pressure_sensor" pos="-0.008 -0.085 0.002" euler="0 -1.5708 0" type="cylinder" size="0.006 0.001" material="black_transparent"/>
                    </body>
                  </body>
                
                  <!-- The tip is driven by a 4 linkage bar where one of the bars is a springy plastic piece. The linkage chain is completed with equality constraints. -->
                  <body name="thumb_spring_rod" pos="0 0.005 0">
                    <geom type="mesh" mesh="tip_spring_rod" material="white" mass="0.002"/>
                    <joint name="thumb_spring_rod" class="limited_joint" axis="1 0 0" pos="0 -0.050728 0.005728" range="0 1.5708"/><!-- 0degrees 90degrees -->
                  </body>
                </body>
              </body>
            
            </body>

            <!-- The index starts at 90mm from the palm origin and an angle of 15 degrees to the center line. -->
            <body name="index_knuckle" pos="0.02329 -0.08693 0" euler="0 0 0.261799">
              <geom type="mesh" mesh="knuckle_gimbal" material="white" mass="0.005"/>
              <joint name="index_yaw" class="limited_joint" axis="0 0 1" range="-0.523599 0.523599"/><!-- 30degrees 30degrees -->

              <!-- The axis of the pitch joint is 15mm offset from the yaw axis, due to sensor space constraints. --> 
              <body name="index_proximal" pos="0 0 0">
                <geom type="mesh" mesh="proximal" material="white" mass="0.027"/>
                <joint name="index_pitch" class="limited_joint" axis="1 0 0" pos="0 -0.015 0" range="0 1.5708"/><!-- 0degrees 90degrees -->

                <!-- The joint is at 50mm from the finger yaw axis. -->
                <body name="index_middle" pos="0 0 0">
                  <geom type="mesh" mesh="middle_segment" material="white" mass="0.013"/>
                  <joint name="index_curl" class="limited_joint" axis="1 0 0" pos="0 -0.045 0" range="0 1.5708"/><!-- 0degrees 90degrees -->

                  <!-- The tip axis joint is 80mm from the yaw axis for the finger. -->
                  <body name="index_tip" pos="0 0 0">
                    <geom type="mesh" mesh="tip" material="white" mass="0.015"/>
                    <joint name="index_tip" class="limited_joint" axis="1 0 0" pos="0 -0.075 0" range="0 1.8326" damping="0.01"/><!-- 0degrees 105degrees -->
                    <site name="index_tip_joint" pos="0 -0.075 0"/>
                    <site name="index_nail_pressure_sensor" pos="0 -0.085 0.0095" type="cylinder" size="0.006 0.001" material="black_transparent"/>
                    <site name="index_tip_pressure_sensor" pos="0 -0.090 -0.0055" euler="-0.523599 0 0" type="cylinder" size="0.006 0.001" material="black_transparent"/>
                    <site name="index_left_pressure_sensor" pos="0.007 -0.085 0.002" euler="0 1.5708 0" type="cylinder" size="0.006 0.001" material="black_transparent"/>
                    <site name="index_right_pressure_sensor" pos="-0.008 -0.085 0.002" euler="0 -1.5708 0" type="cylinder" size="0.006 0.001" material="black_transparent"/>
                  </body>
                </body>

                <!-- The tip is driven by a 4 linkage bar where one of the bars is a springy plastic piece. The linkage chain is completed with equality constraints. -->
                <body name="index_spring_rod" pos="0 0 0">
                  <geom type="mesh" mesh="tip_spring_rod" material="white" mass="0.002"/>
                  <joint name="index_spring_rod" class="limited_joint" axis="1 0 0" pos="0 -0.050728 0.005728" range="0 1.5708"/><!-- 0degrees 90degrees -->
                </body>
              </body>
            </body>

            <!-- The middle starts at 90mm from the palm origin and is aligned with the center line. -->
            <body name="middle_knuckle" pos="0 -0.090 0" euler="0 0 0">
              <geom type="mesh" mesh="knuckle_gimbal" material="white" mass="0.005"/>
              <joint name="middle_yaw" class="limited_joint" axis="0 0 1" range="-0.523599 0.523599"/><!-- 30degrees 30degrees -->

              <!-- The axis of the pitch joint is 15mm offset from the yaw axis, due to sensor space constraints. --> 
              <body name="middle_proximal" pos="0 0 0">
                <geom type="mesh" mesh="proximal" material="white" mass="0.027"/>
                <joint name="middle_pitch" class="limited_joint" axis="1 0 0" pos="0 -0.015 0" range="0 1.5708"/><!-- 0degrees 90degrees -->

                <!-- The joint is at 50mm from the finger yaw axis. -->
                <body name="middle_middle" pos="0 0 0">
                  <geom type="mesh" mesh="middle_segment" material="white" mass="0.013"/>
                  <joint name="middle_curl" class="limited_joint" axis="1 0 0" pos="0 -0.045 0" range="0 1.5708"/><!-- 0degrees 90degrees -->

                  <!-- The tip axis joint is 80mm from the yaw axis for the finger. -->
                  <body name="middle_tip" pos="0 0 0">
                    <geom type="mesh" mesh="tip" material="white" mass="0.015"/>
                    <joint name="middle_tip" class="limited_joint" axis="1 0 0" pos="0 -0.075 0" range="0 1.8326" damping="0.01"/><!-- 0degrees 105degrees -->
                    <site name="middle_tip_joint" pos="0 -0.075 0"/>
                    <site name="middle_nail_pressure_sensor" pos="0 -0.085 0.0095" type="cylinder" size="0.006 0.001" material="black_transparent"/>
                    <site name="middle_tip_pressure_sensor" pos="0 -0.090 -0.0055" euler="-0.523599 0 0" type="cylinder" size="0.006 0.001" material="black_transparent"/>
                    <site name="middle_left_pressure_sensor" pos="0.007 -0.085 0.002" euler="0 1.5708 0" type="cylinder" size="0.006 0.001" material="black_transparent"/>
                    <site name="middle_right_pressure_sensor" pos="-0.008 -0.085 0.002" euler="0 -1.5708 0" type="cylinder" size="0.006 0.001" material="black_transparent"/>
                  </body>
                </body>

                <!-- The tip is driven by a 4 linkage bar where one of the bars is a springy plastic piece. The linkage chain is completed with equality constraints. -->
                <body name="middle_spring_rod" pos="0 0 0">
                  <geom type="mesh" mesh="tip_spring_rod" material="white" mass="0.002"/>
                  <joint name="middle_spring_rod" class="limited_joint" axis="1 0 0" pos="0 -0.050728 0.005728" range="0 1.5708"/><!-- 0degrees 90degrees -->
                </body>
              </body>
            </body>

            <!-- The ring finger starts at 90mm from the palm origin and an angle of 15 degrees to the center line. -->
            <body name="ring_knuckle" pos="-0.02329 -0.08693 0" euler="0 0 -0.261799">
              <geom type="mesh" mesh="knuckle_gimbal" material="white" mass="0.005"/>
              <joint name="ring_yaw" class="limited_joint" axis="0 0 1" range="-0.523599 0.523599"/><!-- 30degrees 30degrees -->

              <!-- The axis of the pitch joint is 15mm offset from the yaw axis, due to sensor space constraints. --> 
              <body name="ring_proximal" pos="0 0 0">
                <geom type="mesh" mesh="proximal" material="white" mass="0.027"/>
                <joint name="ring_pitch" class="limited_joint" axis="1 0 0" pos="0 -0.015 0" range="0 1.5708"/><!-- 0degrees 90degrees -->

                <!-- The joint is at 50mm from the finger yaw axis. -->
                <body name="ring_middle" pos="0 0 0">
                  <geom type="mesh" mesh="middle_segment" material="white" mass="0.013"/>
                  <joint name="ring_curl" class="limited_joint" axis="1 0 0" pos="0 -0.045 0" range="0 1.5708"/><!-- 0degrees 90degrees -->

                  <!-- The tip axis joint is 80mm from the yaw axis for the finger. -->
                  <body name="ring_tip" pos="0 0 0">
                    <geom type="mesh" mesh="tip" material="white" mass="0.015"/>
                    <joint name="ring_tip" class="limited_joint" axis="1 0 0" pos="0 -0.075 0" range="0 1.8326" damping="0.01"/><!-- 0degrees 105degrees -->
                    <site name="ring_tip_joint" pos="0 -0.075 0"/>
                    <site name="ring_nail_pressure_sensor" pos="0 -0.085 0.0095" type="cylinder" size="0.006 0.001" material="black_transparent"/>
                    <site name="ring_tip_pressure_sensor" pos="0 -0.090 -0.0055" euler="-0.523599 0 0" type="cylinder" size="0.006 0.001" material="black_transparent"/>
                    <site name="ring_left_pressure_sensor" pos="0.007 -0.085 0.002" euler="0 1.5708 0" type="cylinder" size="0.006 0.001" material="black_transparent"/>
                    <site name="ring_right_pressure_sensor" pos="-0.008 -0.085 0.002" euler="0 -1.5708 0" type="cylinder" size="0.006 0.001" material="black_transparent"/>
                  </body>
                </body>

                <!-- The tip is driven by a 4 linkage bar where one of the bars is a springy plastic piece. The linkage chain is completed with equality constraints. -->
                <body name="ring_spring_rod" pos="0 0 0">
                  <geom type="mesh" mesh="tip_spring_rod" material="white" mass="0.002"/>
                  <joint name="ring_spring_rod" class="limited_joint" axis="1 0 0" pos="0 -0.050728 0.005728" range="0 1.5708"/><!-- 0degrees 90degrees -->
                </body>
              </body>
            </body>

            <!-- The pinkie pivot functions similar to the thumb pivot and makes the pinkie opposable. It's simmetric with the thumb pivot at 15 degrees angle to the center line. -->
            <body name="pinkie_pivot" pos="0 0 0">
              <geom type="mesh" mesh="pinkie_pivot" material="white" mass="0.010"/>
              <joint name="pinkie_abduct" class="limited_joint" axis="-0.25882 -0.96593 0" range="0 1.0472"/><!-- 0degrees 60degrees -->

              <!-- The pinkie starts at 80mm from the palm origin and an angle of 30 degrees to the center line. -->
              <body name="pinkie_knuckle" pos="-0.04 -0.06928 0" euler="0 0 -0.523599">
                <geom type="mesh" mesh="knuckle_gimbal" material="white" mass="0.005"/>
                <joint name="pinkie_yaw" class="limited_joint" axis="0 0 1" range="-0.523599 0.523599"/><!-- 30degrees 30degrees -->

                <!-- The pinkie uses the shorter proximal segment. The axis of the pitch joint is 15mm offset from the yaw axis, due to sensor space constraints. --> 
                <body name="pinkie_proximal" pos="0 0 0">
                  <geom type="mesh" mesh="squash_proximal" material="white" mass="0.025"/>
                  <joint name="pinkie_pitch" class="limited_joint" axis="1 0 0" pos="0 -0.015 0" range="0 1.5708"/><!-- 0degrees 90degrees -->

                  <!-- The shorter middle segment means the middle segment needs to be offset by 5mm. The joint is at 45mm from the finger yaw axis. -->
                  <body name="pinkie_middle" pos="0 0.005 0">
                    <geom type="mesh" mesh="middle_segment" material="white" mass="0.013"/>
                    <joint name="pinkie_curl" class="limited_joint" axis="1 0 0" pos="0 -0.045 0" range="0 1.5708"/><!-- 0degrees 90degrees -->

                    <!-- The tip axis joint is 75mm from the yaw axis for the stubbier pinkie finger. -->
                    <body name="pinkie_tip" pos="0 0 0">
                      <geom type="mesh" mesh="tip" material="white" mass="0.015"/>
                      <joint name="pinkie_tip" class="limited_joint" axis="1 0 0" pos="0 -0.075 0" range="0 1.8326" damping="0.01"/><!-- 0degrees 105degrees -->
                      <site name="pinkie_tip_joint" pos="0 -0.075 0"/>
                      <site name="pinkie_nail_pressure_sensor" pos="0 -0.085 0.0095" type="cylinder" size="0.006 0.001" material="black_transparent"/>
                      <site name="pinkie_tip_pressure_sensor" pos="0 -0.090 -0.0055" euler="-0.523599 0 0" type="cylinder" size="0.006 0.001" material="black_transparent"/>
                      <site name="pinkie_left_pressure_sensor" pos="0.007 -0.085 0.002" euler="0 1.5708 0" type="cylinder" size="0.006 0.001" material="black_transparent"/>
                      <site name="pinkie_right_pressure_sensor" pos="-0.008 -0.085 0.002" euler="0 -1.5708 0" type="cylinder" size="0.006 0.001" material="black_transparent"/>
                    </body>
                  </body>

                  <!-- The tip is driven by a 4 linkage bar where one of the bars is a springy plastic piece. The linkage chain is completed with equality constraints. -->
                  <body name="pinkie_spring_rod" pos="0 0.005 0">
                    <geom type="mesh" mesh="tip_spring_rod" material="white" mass="0.002"/>
                    <joint name="pinkie_spring_rod" class="limited_joint" axis="1 0 0" pos="0 -0.050728 0.005728" range="0 1.5708"/><!-- 0degrees 90degrees -->
                  </body>
                </body>
              </body>
            </body>

            
          </body>
        </body>
      </body>
    </body>
    
  </worldbody>

  <equality>
    <connect name="thumb_tip_driver" class="tip_spring_rod_constraint" body1="thumb_tip" body2="thumb_spring_rod" anchor="0 -0.078728 -0.005728"/>
    <connect name="index_tip_driver" class="tip_spring_rod_constraint" body1="index_tip" body2="index_spring_rod" anchor="0 -0.078728 -0.005728"/>
    <connect name="middle_tip_driver" class="tip_spring_rod_constraint" body1="middle_tip" body2="middle_spring_rod" anchor="0 -0.078728 -0.005728"/>
    <connect name="ring_tip_driver" class="tip_spring_rod_constraint" body1="ring_tip" body2="ring_spring_rod" anchor="0 -0.078728 -0.005728"/>
    <connect name="pinkie_tip_driver" class="tip_spring_rod_constraint" body1="pinkie_tip" body2="pinkie_spring_rod" anchor="0 -0.078728 -0.005728"/>
  </equality>

  <!-- Exclude additional closeby bodies. We're using the convex hull for collisions so many pieces intersect in the normal pose. -->
  <contact>
    <exclude body1="mount_peg" body2="motor_box"/>
    <exclude body1="motor_box" body2="gimbal_structure"/>
    <exclude body1="motor_box" body2="palm"/>
    <exclude body1="gimbal_structure" body2="palm"/>

    <exclude body1="palm" body2="thumb_pivot"/>
    <exclude body1="palm" body2="pinkie_pivot"/>
    <exclude body1="palm" body2="thumb_knuckle"/>
    <exclude body1="palm" body2="thumb_proximal"/>
    <exclude body1="palm" body2="thumb_middle"/>
    <exclude body1="palm" body2="index_proximal"/>
    <exclude body1="palm" body2="middle_proximal"/>
    <exclude body1="palm" body2="ring_proximal"/> 
    <exclude body1="palm" body2="pinkie_knuckle"/>
    <exclude body1="palm" body2="pinkie_proximal"/>
    <exclude body1="palm" body2="pinkie_middle"/>

    <exclude body1="thumb_pivot" body2="pinkie_pivot"/>
    <exclude body1="thumb_pivot" body2="thumb_knuckle"/>
    <exclude body1="thumb_pivot" body2="thumb_proximal"/>
    <exclude body1="thumb_knuckle" body2="thumb_proximal"/>
    <exclude body1="pinkie_pivot" body2="pinkie_knuckle"/>
    <exclude body1="pinkie_pivot" body2="pinkie_proximal"/>
    <exclude body1="pinkie_knuckle" body2="pinkie_proximal"/>

    <!-- All the spring rods pass right through the middle segment so we need to exclude its collisions. -->
    <exclude body1="thumb_spring_rod" body2="thumb_middle"/>
    <exclude body1="thumb_spring_rod" body2="thumb_tip"/>

    <exclude body1="index_spring_rod" body2="index_middle"/>
    <exclude body1="index_spring_rod" body2="index_tip"/>
    
    <exclude body1="middle_spring_rod" body2="middle_middle"/>
    <exclude body1="middle_spring_rod" body2="middle_tip"/>

    <exclude body1="ring_spring_rod" body2="ring_middle"/>
    <exclude body1="ring_spring_rod" body2="ring_tip"/>

    <exclude body1="pinkie_spring_rod" body2="pinkie_middle"/>
    <exclude body1="pinkie_spring_rod" body2="pinkie_tip"/>
  </contact>

  <tendon>
  </tendon>

  <!-- Name, range and force settings for the actuators. 

  The actuators on the physical robot run a position PID loop with configurable parameters 
  and also have current/torque control via an on-board current PID loop. The actuators can be set
  to a target position with a torque limit or to a target torque level. The driver limits the
  continous motor current to prevent overheating.

  In MuJoCo I think the control logic should just use the actuator target position.
  
  In total there are the following actuators:
    * 20 position actuators
      - 3 per finger: curl (flexing the finger tip), pitch (flexing the whole finger), yaw (moving the finger sideways)
      - 2 extra for thumb and pinkie opposable movement
      - 3 for the wrist: pitch, yaw, roll
  -->
  <actuator>
    <position name="thumb_curl" joint="thumb_curl" kp="0.4" ctrlrange="-0.261799 1.8326" forcerange="-0.6 0.6"/><!-- -15degrees 105degrees -->
    <position name="thumb_pitch" joint="thumb_pitch" kp="0.4" ctrlrange="-0.261799 1.8326" forcerange="-0.6 0.6"/><!-- -15degrees 105degrees -->
    <position name="thumb_yaw" joint="thumb_yaw" kp="0.4" ctrlrange="-0.698132 0.698132" forcerange="-0.6 0.6"/><!-- -40degrees 40degrees -->
    <position name="index_curl" joint="index_curl" kp="0.4" ctrlrange="-0.261799 1.8326" forcerange="-0.6 0.6"/><!-- -15degrees 105degrees -->
    <position name="index_pitch" joint="index_pitch" kp="0.4" ctrlrange="-0.261799 1.8326" forcerange="-0.6 0.6"/><!-- -15degrees 105degrees -->
    <position name="index_yaw" joint="index_yaw" kp="0.4" ctrlrange="-0.698132 0.698132" forcerange="-0.6 0.6"/><!-- -40degrees 40degrees -->
    <position name="middle_curl" joint="middle_curl" kp="0.4" ctrlrange="-0.261799 1.8326" forcerange="-0.6 0.6"/><!-- -15degrees 105degrees -->
    <position name="middle_pitch" joint="middle_pitch" kp="0.4" ctrlrange="-0.261799 1.8326" forcerange="-0.6 0.6"/><!-- -15degrees 105degrees -->
    <position name="middle_yaw" joint="middle_yaw" kp="0.4" ctrlrange="-0.698132 0.698132" forcerange="-0.6 0.6"/><!-- -40degrees 40degrees -->
    <position name="ring_curl" joint="ring_curl" kp="0.4" ctrlrange="-0.261799 1.8326" forcerange="-0.6 0.6"/><!-- -15degrees 105degrees -->
    <position name="ring_pitch" joint="ring_pitch" kp="0.4" ctrlrange="-0.261799 1.8326" forcerange="-0.6 0.6"/><!-- -15degrees 105degrees -->
    <position name="ring_yaw" joint="ring_yaw" kp="0.4" ctrlrange="-0.698132 0.698132" forcerange="-0.6 0.6"/><!-- -40degrees 40degrees -->
    <position name="pinkie_curl" joint="pinkie_curl" kp="0.4" ctrlrange="-0.261799 1.8326" forcerange="-0.6 0.6"/><!-- -15degrees 105degrees -->
    <position name="pinkie_pitch" joint="pinkie_pitch" kp="0.4" ctrlrange="-0.261799 1.8326" forcerange="-0.6 0.6"/><!-- -15degrees 105degrees -->
    <position name="pinkie_yaw" joint="pinkie_yaw" kp="0.4" ctrlrange="-0.698132 0.698132" forcerange="-0.6 0.6"/><!-- -40degrees 40degrees -->
    <position name="pinkie_abduct" joint="pinkie_abduct" kp="0.4" ctrlrange="-0.261799 1.309" forcerange="-0.4 0.4"/><!-- -15degrees 75degrees -->
    <position name="thumb_abduct" joint="thumb_abduct" kp="0.4" ctrlrange="-0.261799 1.8326" forcerange="-0.6 0.6"/><!-- -15degrees 105degrees -->
    <position name="wrist_yaw" joint="wrist_yaw" kp="1.5" ctrlrange="-0.523599 0.523599" forcerange="-0.8 0.8"/><!-- -30degrees 30degrees -->
    <position name="wrist_pitch" joint="wrist_pitch" kp="1.5" ctrlrange="-0.698132 1.22173" forcerange="-0.8 0.8"/><!-- -40degrees 70degrees -->
    <position name="wrist_roll" joint="wrist_roll" kp="2.0" ctrlrange="-1.309 1.309" forcerange="-1.0 1.0"/><!-- -75degrees 75degrees -->
  </actuator>

  <!-- Define the sensors accessible from the robot hand sensor suite.
  
  MuJoCo offers detailed information about all the joints, but not all of those are available 
  on a physical robot unless there are sensors to measure them. The sensors defined below
  represent the measurements available from the physical robot. There are on axis position
  sensors for every joint accurate to 0.1 degrees (within load tolerance). There are also
  force sensors on the fingertips and the palm integrated into the circuit which measures
  position of the fingers. The actuator motors on the physical robot have current feedback
  and can therefore be calibrated to measure output torque. Finally the finger tip passive
  joint is connected via a 4 bar linkage, with a springy 4th link, to the finger curl joint.
  This enables the measurement of torque or the finger tip joint. In the MuJoCo model this
  is simulated using the equality constraint so I'm not sure if the same calculation applies
  as in the real robot, however I expose the finger tip torque directly as measured by the
  MoJoCo torque sensor between finger tip segment and finger middle segment.

  In total there are the following sensors:
    * 25 rotational position sensors
      - 4 per finger; 5 fingers: tip (passive joint), curl, pitch, yaw; thumb, index, middle, ring, pinkie.
      - 2 extra for thumb and pinkie opposable movement.
      - 3 for wrist: yaw, pitch, roll 
    * 24 force sensors
      - 4 per finger: finger_nail, finger_tip, finger_left, finger_right
      - 4 for palm: palm_inside_left, palm_inside_right, palm_outside_left, palm_outside_right
    * 5 finger tip torque sensors
      - 1 per finger: thumb, index, middle, ring, pinkie
    * 20 current/torque sensors
      - 3 per finger: curl, pitch, yaw
      - 2 for thumb and pinkie opposable movement
      - 3 for wrist: yaw, pitch, roll
    * 1 accelerometer on the forearm
  -->
  <sensor>
    <!-- Copy joint positions as we have on-axis sensors to measure them. -->
    <jointpos name="thumb_tip" joint="thumb_tip"/>
    <jointpos name="thumb_curl" joint="thumb_curl"/>
    <jointpos name="thumb_pitch" joint="thumb_pitch"/>
    <jointpos name="thumb_yaw" joint="thumb_yaw"/>
    <jointpos name="index_tip" joint="index_tip"/>
    <jointpos name="index_curl" joint="index_curl"/>
    <jointpos name="index_pitch" joint="index_pitch"/>
    <jointpos name="index_yaw" joint="index_yaw"/>
    <jointpos name="middle_tip" joint="middle_tip"/>
    <jointpos name="middle_curl" joint="middle_curl"/>
    <jointpos name="middle_pitch" joint="middle_pitch"/>
    <jointpos name="middle_yaw" joint="middle_yaw"/>
    <jointpos name="ring_tip" joint="ring_tip"/>
    <jointpos name="ring_curl" joint="ring_curl"/>
    <jointpos name="ring_pitch" joint="ring_pitch"/>
    <jointpos name="ring_yaw" joint="ring_yaw"/>
    <jointpos name="pinkie_tip" joint="pinkie_tip"/>
    <jointpos name="pinkie_curl" joint="pinkie_curl"/>
    <jointpos name="pinkie_pitch" joint="pinkie_pitch"/>
    <jointpos name="pinkie_yaw" joint="pinkie_yaw"/>
    <jointpos name="thumb_abduct" joint="thumb_abduct"/>
    <jointpos name="pinkie_abduct" joint="pinkie_abduct"/>
    <jointpos name="wrist_yaw" joint="wrist_yaw"/>
    <jointpos name="wrist_pitch" joint="wrist_pitch"/>
    <jointpos name="wrist_roll" joint="wrist_roll"/>

    <!-- The robot has integrated force sensors in the palm and fingertips. -->
    <touch name="thumb_nail_pressure" site="thumb_nail_pressure_sensor"/>
    <touch name="thumb_tip_pressure" site="thumb_tip_pressure_sensor"/>
    <touch name="thumb_left_pressure" site="thumb_left_pressure_sensor"/>
    <touch name="thumb_right_pressure" site="thumb_right_pressure_sensor"/>
    <touch name="index_nail_pressure" site="index_nail_pressure_sensor"/>
    <touch name="index_tip_pressure" site="index_tip_pressure_sensor"/>
    <touch name="index_left_pressure" site="index_left_pressure_sensor"/>
    <touch name="index_right_pressure" site="index_right_pressure_sensor"/>
    <touch name="middle_nail_pressure" site="middle_nail_pressure_sensor"/>
    <touch name="middle_tip_pressure" site="middle_tip_pressure_sensor"/>
    <touch name="middle_left_pressure" site="middle_left_pressure_sensor"/>
    <touch name="middle_right_pressure" site="middle_right_pressure_sensor"/>
    <touch name="ring_nail_pressure" site="ring_nail_pressure_sensor"/>
    <touch name="ring_tip_pressure" site="ring_tip_pressure_sensor"/>
    <touch name="ring_left_pressure" site="ring_left_pressure_sensor"/>
    <touch name="ring_right_pressure" site="ring_right_pressure_sensor"/>
    <touch name="pinkie_nail_pressure" site="pinkie_nail_pressure_sensor"/>
    <touch name="pinkie_tip_pressure" site="pinkie_tip_pressure_sensor"/>
    <touch name="pinkie_left_pressure" site="pinkie_left_pressure_sensor"/>
    <touch name="pinkie_right_pressure" site="pinkie_right_pressure_sensor"/>
    <touch name="palm_inside_left_pressure" site="palm_inside_left_pressure_sensor"/>
    <touch name="palm_inside_right_pressure" site="palm_inside_right_pressure_sensor"/>
    <touch name="palm_outside_left_pressure" site="palm_outside_left_pressure_sensor"/>
    <touch name="palm_outside_right_pressure" site="palm_outside_right_pressure_sensor"/>

    <!-- In the real robot we can calculate tip torque based on the elastic constant of
    the springy 4 bar linkage and the position of rotation sensor for the tip and middle
    finger segments (distal interphalangeal joint DIP and proximal interphalangeal joint PIP).
    
    In the MuJoCo modelwe can directly read the torque between the tip and middle segments.

    Unfortunately I'm not sure if the 4 link bar can be simulated accurately enough to obtain
    the same behaviour as the real robot in terms of the tip rotation angle differences. A
    better solution would be to expose the distance used in the equality constraint that connects
    the tip spring rod and finger tip segment. That option is not available in the default sensors.
    -->
    <torque name="thumb_tip_torque" site="thumb_tip_joint"/>
    <torque name="index_tip_torque" site="index_tip_joint"/>
    <torque name="middle_tip_torque" site="middle_tip_joint"/>
    <torque name="ring_tip_torque" site="ring_tip_joint"/>
    <torque name="pinkie_tip_torque" site="pinkie_tip_joint"/>

    <!-- Copy actuator forces as there is current feedback for the motors. -->
    <actuatorfrc name="thumb_curl_force" actuator="thumb_curl"/>
    <actuatorfrc name="thumb_pitch_force" actuator="thumb_pitch"/>
    <actuatorfrc name="thumb_yaw_force" actuator="thumb_yaw"/>
    <actuatorfrc name="index_curl_force" actuator="index_curl"/>
    <actuatorfrc name="index_pitch_force" actuator="index_pitch"/>
    <actuatorfrc name="index_yaw_force" actuator="index_yaw"/>
    <actuatorfrc name="middle_curl_force" actuator="middle_curl"/>
    <actuatorfrc name="middle_pitch_force" actuator="middle_pitch"/>
    <actuatorfrc name="middle_yaw_force" actuator="middle_yaw"/>
    <actuatorfrc name="ring_curl_force" actuator="ring_curl"/>
    <actuatorfrc name="ring_pitch_force" actuator="ring_pitch"/>
    <actuatorfrc name="ring_yaw_force" actuator="ring_yaw"/>
    <actuatorfrc name="pinkie_curl_force" actuator="pinkie_curl"/>
    <actuatorfrc name="pinkie_pitch_force" actuator="pinkie_pitch"/>
    <actuatorfrc name="pinkie_yaw_force" actuator="pinkie_yaw"/>
    <actuatorfrc name="thumb_abduct_force" actuator="thumb_abduct"/>
    <actuatorfrc name="pinkie_abduct_force" actuator="pinkie_abduct"/>
    <actuatorfrc name="wrist_yaw_force" actuator="wrist_yaw"/>
    <actuatorfrc name="wrist_pitch_force" actuator="wrist_pitch"/>
    <actuatorfrc name="wrist_roll_force" actuator="wrist_roll"/>

    <!-- The motor driver board on the forearm contains an inertial measurement unit IMU. -->
    <accelerometer name="accelerometer" site="motor_box_IMU"/>
    <gyro name="gyro" site="motor_box_IMU"/>

  </sensor>
</mujoco>